Workbook
Name B: 'Inputs'!$B$4
Name H: 'Inputs'!$B$5
Name t_w: 'Inputs'!$B$6
Name t_s: 'Inputs'!$B$7
Name L_L: 'Inputs'!$B$8
Name gamma_concrete: 'Inputs'!$B$9
Name h_wt: 'Inputs'!$B$12
Name w_C: 'Inputs'!$B$15
Name w_L: 'Inputs'!$B$16
Name n_layers: 'Inputs'!$B$19
Name t_1: Inputs!$B$21
Name gamma_1: Inputs!$C$21
Name t_2: Inputs!$B$22
Name gamma_2: Inputs!$C$22
Name t_3: Inputs!$B$23
Name gamma_3: Inputs!$C$23
Name layer_t_range: Inputs!$B$21:$B$23
Name phi_backfill: 'Inputs'!$B$26
Name gamma_backfill: 'Inputs'!$B$27
Name H_ob: 'Inputs'!$B$28
Name phi_founding: 'Inputs'!$B$29
Name gamma_founding: 'Inputs'!$B$30
Name sv_vehicle: Inputs!$B$33
Name SelfWeight_sup_SLS: PartialFactors!$B$5
Name SelfWeight_sup_EQU: PartialFactors!$C$5
Name SelfWeight_sup_STR_GEO_Comb1: PartialFactors!$D$5
Name SelfWeight_sup_STR_GEO_Comb2: PartialFactors!$E$5
Name Superimposed_sup_SLS: PartialFactors!$B$6
Name Superimposed_sup_EQU: PartialFactors!$C$6
Name Superimposed_sup_STR_GEO_Comb1: PartialFactors!$D$6
Name Superimposed_sup_STR_GEO_Comb2: PartialFactors!$E$6
Name RoadTraffic_sup_SLS: PartialFactors!$B$7
Name RoadTraffic_sup_EQU: PartialFactors!$C$7
Name RoadTraffic_sup_STR_GEO_Comb1: PartialFactors!$D$7
Name RoadTraffic_sup_STR_GEO_Comb2: PartialFactors!$E$7
Name MaterialM_SLS: PartialFactors!$B$8
Name MaterialM_EQU: PartialFactors!$C$8
Name MaterialM_STR_GEO_Comb1: PartialFactors!$D$8
Name MaterialM_STR_GEO_Comb2: PartialFactors!$E$8
Name WaterPressure_sup_SLS: PartialFactors!$B$9
Name WaterPressure_sup_EQU: PartialFactors!$C$9
Name WaterPressure_sup_STR_GEO_Comb1: PartialFactors!$D$9
Name WaterPressure_sup_STR_GEO_Comb2: PartialFactors!$E$9
Name SelfWeight_inf_SLS: PartialFactors!$B$13
Name SelfWeight_inf_EQU: PartialFactors!$C$13
Name SelfWeight_inf_STR_GEO_Comb1: PartialFactors!$D$13
Name SelfWeight_inf_STR_GEO_Comb2: PartialFactors!$E$13
Name Superimposed_inf_SLS: PartialFactors!$B$14
Name Superimposed_inf_EQU: PartialFactors!$C$14
Name Superimposed_inf_STR_GEO_Comb1: PartialFactors!$D$14
Name Superimposed_inf_STR_GEO_Comb2: PartialFactors!$E$14
Name road_dev_unfav: 'PartialFactors'!$B$16
Name road_dev_fav: 'PartialFactors'!$B$17
Name gamma_sd_ec: 'PartialFactors'!$B$18
Name gamma_w: 'PartialFactors'!$B$19
Name Ka_traffic_SLS: PartialFactors!$B$23
Name Ka_traffic_EQU: PartialFactors!$C$23
Name Ka_traffic_STR_GEO_Comb1: PartialFactors!$D$23
Name Ka_traffic_STR_GEO_Comb2: PartialFactors!$E$23
Name Ka_earth_SLS: PartialFactors!$B$24

Sheet Inputs
A1: Culvert Stability — Inputs
A3: Culvert Geometry
A4: Internal Width, B (m) | B4: 2.5
A5: Internal Height, H (m) | B5: 2
A6: Wall Thickness, t_w (m) | B6: 0.3
A7: Slab Thickness, t_s (m) | B7: 0.3
A8: Overall Length, L_L (m) | B8: 20.6
A9: Concrete Density, gamma_concrete (kN/m3) | B9: 25
A11: Water Table
A12: Water Table, h_wt (m) — height above culvert invert | B12: 0
A14: Road Geometry
A15: Carriageway Width, w_C (m) | B15: 7.3
A16: Lane Width, w_L (m) | B16: 3.65
A18: Cover Layers (top to bottom, up to 3)
A19: Number of cover layers (1-3) | B19: 3
A20: Layer | B20: Thickness t_i (mm) | C20: Unit Weight gamma_i (kN/m3)
A21: Layer 1 | B21: 200 | C21: 24
A22: Layer 2 | B22: 500 | C22: 19
A23: Layer 3 | B23: 300 | C23: 20
A25: Soil Properties
A26: Backfill Friction Angle, phi_backfill (deg) | B26: 30
A27: Backfill Density, gamma_backfill (kN/m3) | B27: 19
A28: Overburden Depth, H_ob (m) | B28: 0.6
A29: Founding Friction Angle, phi_founding (deg) | B29: 32
A30: Founding Density, gamma_founding (kN/m3) | B30: 19
A32: LM3 Vehicle Type
A33: SV Vehicle (SV80 / SV100 / SV196) | B33: SV196
A35: Yellow cells are inputs — edit these. Everything else recalculates automatically.

Sheet Summary
A1: Summary — Governing Utilisation
A3: Highest utilisation (%) across all four limit states and both LM1/LM3, per table.
A5: Check | B5: Utilisation (%) | C5: Status
A6: Table B.4 — Sliding | B6: =MAX('TableB4'!B35,'TableB4'!B57,'TableB4'!B98,'TableB4'!B120,'TableB4'!B161,'TableB4'!B183,'TableB4'!B224,'TableB4'!B246) | C6: =IF(B6<=100,"OK","Review required")
A7: Table B.4 — Overturning | B7: =MAX('TableB4'!B42,'TableB4'!B64,'TableB4'!B105,'TableB4'!B127,'TableB4'!B168,'TableB4'!B190,'TableB4'!B231,'TableB4'!B253) | C7: =IF(B7<=100,"OK","Review required")
A8: Table B.5 — Sliding | B8: =MAX('TableB5'!B35,'TableB5'!B57,'TableB5'!B98,'TableB5'!B120,'TableB5'!B161,'TableB5'!B183,'TableB5'!B224,'TableB5'!B246) | C8: =IF(B8<=100,"OK","Review required")
A9: Table B.5 — Overturning | B9: =MAX('TableB5'!B42,'TableB5'!B64,'TableB5'!B105,'TableB5'!B127,'TableB5'!B168,'TableB5'!B190,'TableB5'!B231,'TableB5'!B253) | C9: =IF(B9<=100,"OK","Review required")
A10: Table B.6 — Sliding | B10: =MAX('TableB6'!B40,'TableB6'!B62,'TableB6'!B104,'TableB6'!B126,'TableB6'!B168,'TableB6'!B190,'TableB6'!B232,'TableB6'!B254) | C10: =IF(B10<=100,"OK","Review required")
A11: Table B.6 — Overturning | B11: =MAX('TableB6'!B47,'TableB6'!B69,'TableB6'!B111,'TableB6'!B133,'TableB6'!B175,'TableB6'!B197,'TableB6'!B239,'TableB6'!B261) | C11: =IF(B11<=100,"OK","Review required")
A13: Conditional formatting: green if <= 100%, red if > 100%.

Sheet PartialFactors
A1: UK NA to BS EN 1990 — Partial Factors gamma_F
A3: Unfavourable
A4: Row | B4: SLS | C4: EQU | D4: STR/GEO Comb1 | E4: STR/GEO Comb2
A5: Self weight of structure & backfill, gamma_G;sup | B5: 1 | C5: 1.05 | D5: 1.35 | E5: 1
A6: Superimposed permanent load, gamma_G;sup | B6: 1 | C6: 1.05 | D6: 1.2 | E6: 1
A7: Road traffic action on box, gamma_Q;sup | B7: 1 | C7: 1.35 | D7: 1.35 | E7: 1.15
A8: Material factor to phi', gamma_M | B8: 1 | C8: 1.1 | D8: 1 | E8: 1.25
A9: Vertical and horizontal water pressures, gamma_G;sup | B9: 0 | C9: 1 | D9: 1 | E9: 1
A11: Favourable
A12: Row | B12: SLS | C12: EQU | D12: STR/GEO Comb1 | E12: STR/GEO Comb2
A13: Self weight of structure & backfill, gamma_G;inf | B13: 1 | C13: 0.95 | D13: 0.95 | E13: 1
A14: Superimposed permanent load, gamma_G;inf | B14: 1 | C14: 0.95 | D14: 0.95 | E14: 1
A16: Road construction deviation, unfavourable (+55%) | B16: 1.55
A17: Road construction deviation, favourable (-40%) | B17: 0.6
A18: Model factor gamma_Sd;ec (Cl. 10.2.2) | B18: 1.15
A19: Water unit weight, gamma_w (kN/m3) | B19: 9.81
A21: Table B.4/B.5/B.6 — Earth Pressure Coefficients
A22: Combo | B22: SLS | C22: EQU | D22: STR/GEO Comb1 | E22: STR/GEO Comb2
A23: Ka_traffic | B23: 0.33 | C23: 0.37 | D23: 0.33 | E23: 0.41
A24: Ka_earth | B24: 0.33 | C24: 0.44 | D24: 0.4 | E24: 0.49
A25: Kmax | B25: 0.6 | C25: 0.6 | D25: 0.72 | E25: 0.84

Sheet GlobalCalcs
A1: Global Calculations
A3: Self-Weights (per 1 m length)
A4: B_ext = B + 2*t_w (m) | B4: =B+2*t_w
A5: H_ext = H + 2*t_s (m) | B5: =H+2*t_s
A6: A_conc = B_ext*H_ext - B*H (m2) | B6: =B_ext*H_ext-B*H
A7: W_box = A_conc * gamma_concrete (kN/m) | B7: =A_conc*gamma_concrete
A9: Cover Layer Self-Weights
A10: Layer | B10: Active? | C10: UDL_i = gamma_i*(t_i/1000) (kN/m)
A11: Layer 1 | B11: =1<=n_layers | C11: =IF(1<=n_layers, gamma_1*(t_1/1000), 0)
A12: Layer 2 | B12: =2<=n_layers | C12: =IF(2<=n_layers, gamma_2*(t_2/1000), 0)
A13: Layer 3 | B13: =3<=n_layers | C13: =IF(3<=n_layers, gamma_3*(t_3/1000), 0)
A14: UDL_total (kN/m) | B14: =SUM(C11:C13)
A16: Horizontal Surcharge Model for LM1, LM2 & LM3
A17: H_c = sum(active t_i)/1000 (m) | B17: =(t_1 + IF(n_layers>=2,t_2,0) + IF(n_layers>=3,t_3,0))/1000
A18: Reduction factor = (1-H_c/2)^2 | B18: =(1-H_c/2)^2
A19: F_hll_1m_coeff = 2*reduction_factor*330/w_L (coeff. of Kd, kN) | B19: =2*reduction_factor*330/w_L
A21: F_hUDL_LM12 = 20*Kd kN/m2, F_hUDL_LM3 = 30*Kd kN/m2 (applied directly in Table B.4/5/6)

Sheet LM1
A1: LM1 Calculations — Maximum Vertical Load & Braking
A3: Notional Lanes
A4: n_lanes = INT(w_C / 3) | B4: =INT(w_C/3)
A5: Notional Lane Width (m) | B5: 3
A6: Remaining width = w_C - n_lanes*3 (m) | B6: =w_C-n_lanes*notional_lane_width
A8: UDL & TS per Lane (BS EN 1991-2 Table 4.2, UK NA alpha factors)
A9: Lane | B9: Active? | C9: alpha_qi | D9: qik (kN/m2) | E9: UDL_i (kN/m2) | F9: Qi,TS (kN)
A10: Lane 1 | B10: =1<=n_lanes | C10: 0.61 | D10: 9 | E10: =C10*D10 | F10: 300
A11: Lane 2 | B11: =2<=n_lanes | C11: 2.2 | D11: 2.5 | E11: =C11*D11 | F11: 200
A12: Lane 3 | B12: =3<=n_lanes | C12: 2.2 | D12: 2.5 | E12: =C12*D12 | F12: 100
A14: Contact Patch & Dispersal Through Fill
A15: Contact patch (mm) | B15: 400
A16: tan(30deg) | B16: =TAN(RADIANS(30))
A17: Dispersed patch = contact_patch + 2*H_c*1000*tan_30 (mm) | B17: =contact_patch+2*H_c*1000*tan_30
A18: disp_m (m) | B18: =B17/1000
A20: Transverse Dispersal (Figure 11) — lanes 1 & 2
A21: W1 = lane1_ts / 2 (kN) | B21: =lane1_ts/2
A22: W2 = lane2_ts / 2 (kN) | B22: =lane2_ts/2
A23: Gap between lanes 1 & 2 = 3.0 - 2.0 (m) | B23: =notional_lane_width-2
A24: Overlap a = MAX(disp_m - gap, 0) (m) | B24: =MAX(disp_m-B23,0)
A25: F_transverse_1m (kN/m) | B25: =IF(n_lanes>=2, 1*B21/disp_m + B24*B22/disp_m, B21/disp_m)
A27: Longitudinal Dispersal
A28: Patch load = F_transverse_1m / disp_m (kN/m) | B28: =F_transverse_1m/disp_m
A30: Braking and Acceleration Forces
A31: term1 = 0.6*alpha_Q1*(2*Q1k), alpha_Q1=1.0 | B31: =0.6*1*(2*lane1_ts)
A32: term2 = 0.1*alpha_q1*q1k*w1*L, alpha_q1=1.0, w1=3.0, L=B_ext | B32: =0.1*1*D10*notional_lane_width*B_ext
A33: Q_lk,raw = term1 + term2 (kN) | B33: =B31+B32
A34: Q_lk,clamped = MAX(180, MIN(900, Q_lk,raw)) (kN) | B34: =MAX(180,MIN(900,B33))
A35: Reduction factor eta (H_c<0.6: 1; H_c<B_ext: (B_ext-H_c)/(B_ext-0.6); else 0) | B35: =IF(H_c<0.6,1,IF(H_c<B_ext,(B_ext-H_c)/(B_ext-0.6),0))
A36: Q_lk = eta * Q_lk,clamped (kN) | B36: =B35*B34

Sheet LM3
A1: LM3 Calculations — Special Vehicle (SV) Maximum Vertical Load & Braking
A3: Wheel Dispersal Through Fill
A4: Wheel contact patch, L_L direction (m) | B4: 0.35
A5: Wheel contact patch, B_ext direction (m) | B5: 0.35
A6: Wheel spacing, L_L direction (m) | B6: 2.65
A7: tan(30deg) | B7: =TAN(RADIANS(30))
A8: Dispersed width per wheel, L_L direction = contact_t + 2*tan30*H_c (m) | B8: =sv_contact_t+2*lm3_tan_30*H_c
A9: Gap between wheels' dispersed zones = wheel_spacing - dispersed width (m) | B9: =sv_wheel_spacing-B8
A10: disp_LL (m) — merged if gap<0, else zones stay separate | B10: =IF(B9>=0, 2*B8, sv_wheel_spacing+B8)
A11: disp_B (m) — dispersed width per axle, B_ext direction | B11: =sv_contact_l+2*lm3_tan_30*H_c
A12: half_B = disp_B / 2 (m) | B12: =disp_B/2
A14: Worst-Case Position — SV80
A15: SV80 — inter-group gap = 1.2 m
A16: Axle | B16: Position (m) | C16: Basic Load (kN) | D16: DAF | E16: Factored Load (kN)
A17: 1 | B17: 0 | C17: 130 | D17: 1.16 | E17: =C17*D17
A18: 2 | B18: 1.2 | C18: 130 | D18: 1.16 | E18: =C18*D18
A19: 3 | B19: 2.4 | C19: 130 | D19: 1.16 | E19: =C19*D19
A20: 4 | B20: 3.6 | C20: 130 | D20: 1.16 | E20: =C20*D20
A21: 5 | B21: 4.8 | C21: 130 | D21: 1.16 | E21: =C21*D21
A22: 6 | B22: 6 | C22: 130 | D22: 1.16 | E22: =C22*D22
A24: Breakpoint candidate offset | B24: Offset (m) | C24: Total landed load at this offset (kN/m)
A25: axle 1, right=0 | B25: =-half_B-$B$17 | C25: =SUMPRODUCT($E$17:$E$22*(((((($B25+$B$17:$B$22+half_B)+B_ext-ABS(($B25+$B$17:$B$22+half_B)-B_ext))/2)-((($B25+$B$17:$B$22-half_B)+ABS(($B25+$B$17:$B$22-half_B)))/2))+ABS((((($B25+$B$17:$B$22+half_B)+B_ext-ABS(($B25+$B$17:$B$22+half_B)-B_ext))/2)-((($B25+$B$17:$B$22-half_B)+ABS(($B25+$B$17:$B$22-half_B)))/2))))/2))/disp_B/disp_LL
A26: axle 1, right=B_ext | B26: =B_ext-half_B-$B$17 | C26: =SUMPRODUCT($E$17:$E$22*(((((($B26+$B$17:$B$22+half_B)+B_ext-ABS(($B26+$B$17:$B$22+half_B)-B_ext))/2)-((($B26+$B$17:$B$22-half_B)+ABS(($B26+$B$17:$B$22-half_B)))/2))+ABS((((($B26+$B$17:$B$22+half_B)+B_ext-ABS(($B26+$B$17:$B$22+half_B)-B_ext))/2)-((($B26+$B$17:$B$22-half_B)+ABS(($B26+$B$17:$B$22-half_B)))/2))))/2))/disp_B/disp_LL
A27: axle 1, left=0 | B27: =half_B-$B$17 | C27: =SUMPRODUCT($E$17:$E$22*(((((($B27+$B$17:$B$22+half_B)+B_ext-ABS(($B27+$B$17:$B$22+half_B)-B_ext))/2)-((($B27+$B$17:$B$22-half_B)+ABS(($B27+$B$17:$B$22-half_B)))/2))+ABS((((($B27+$B$17:$B$22+half_B)+B_ext-ABS(($B27+$B$17:$B$22+half_B)-B_ext))/2)-((($B27+$B$17:$B$22-half_B)+ABS(($B27+$B$17:$B$22-half_B)))/2))))/2))/disp_B/disp_LL
A28: axle 1, left=B_ext | B28: =B_ext+half_B-$B$17 | C28: =SUMPRODUCT($E$17:$E$22*(((((($B28+$B$17:$B$22+half_B)+B_ext-ABS(($B28+$B$17:$B$22+half_B)-B_ext))/2)-((($B28+$B$17:$B$22-half_B)+ABS(($B28+$B$17:$B$22-half_B)))/2))+ABS((((($B28+$B$17:$B$22+half_B)+B_ext-ABS(($B28+$B$17:$B$22+half_B)-B_ext))/2)-((($B28+$B$17:$B$22-half_B)+ABS(($B28+$B$17:$B$22-half_B)))/2))))/2))/disp_B/disp_LL
A29: axle 2, right=0 | B29: =-half_B-$B$18 | C29: =SUMPRODUCT($E$17:$E$22*(((((($B29+$B$17:$B$22+half_B)+B_ext-ABS(($B29+$B$17:$B$22+half_B)-B_ext))/2)-((($B29+$B$17:$B$22-half_B)+ABS(($B29+$B$17:$B$22-half_B)))/2))+ABS((((($B29+$B$17:$B$22+half_B)+B_ext-ABS(($B29+$B$17:$B$22+half_B)-B_ext))/2)-((($B29+$B$17:$B$22-half_B)+ABS(($B29+$B$17:$B$22-half_B)))/2))))/2))/disp_B/disp_LL
A30: axle 2, right=B_ext | B30: =B_ext-half_B-$B$18 | C30: =SUMPRODUCT($E$17:$E$22*(((((($B30+$B$17:$B$22+half_B)+B_ext-ABS(($B30+$B$17:$B$22+half_B)-B_ext))/2)-((($B30+$B$17:$B$22-half_B)+ABS(($B30+$B$17:$B$22-half_B)))/2))+ABS((((($B30+$B$17:$B$22+half_B)+B_ext-ABS(($B30+$B$17:$B$22+half_B)-B_ext))/2)-((($B30+$B$17:$B$22-half_B)+ABS(($B30+$B$17:$B$22-half_B)))/2))))/2))/disp_B/disp_LL
A31: axle 2, left=0 | B31: =half_B-$B$18 | C31: =SUMPRODUCT($E$17:$E$22*(((((($B31+$B$17:$B$22+half_B)+B_ext-ABS(($B31+$B$17:$B$22+half_B)-B_ext))/2)-((($B31+$B$17:$B$22-half_B)+ABS(($B31+$B$17:$B$22-half_B)))/2))+ABS((((($B31+$B$17:$B$22+half_B)+B_ext-ABS(($B31+$B$17:$B$22+half_B)-B_ext))/2)-((($B31+$B$17:$B$22-half_B)+ABS(($B31+$B$17:$B$22-half_B)))/2))))/2))/disp_B/disp_LL
A32: axle 2, left=B_ext | B32: =B_ext+half_B-$B$18 | C32: =SUMPRODUCT($E$17:$E$22*(((((($B32+$B$17:$B$22+half_B)+B_ext-ABS(($B32+$B$17:$B$22+half_B)-B_ext))/2)-((($B32+$B$17:$B$22-half_B)+ABS(($B32+$B$17:$B$22-half_B)))/2))+ABS((((($B32+$B$17:$B$22+half_B)+B_ext-ABS(($B32+$B$17:$B$22+half_B)-B_ext))/2)-((($B32+$B$17:$B$22-half_B)+ABS(($B32+$B$17:$B$22-half_B)))/2))))/2))/disp_B/disp_LL
A33: axle 3, right=0 | B33: =-half_B-$B$19 | C33: =SUMPRODUCT($E$17:$E$22*(((((($B33+$B$17:$B$22+half_B)+B_ext-ABS(($B33+$B$17:$B$22+half_B)-B_ext))/2)-((($B33+$B$17:$B$22-half_B)+ABS(($B33+$B$17:$B$22-half_B)))/2))+ABS((((($B33+$B$17:$B$22+half_B)+B_ext-ABS(($B33+$B$17:$B$22+half_B)-B_ext))/2)-((($B33+$B$17:$B$22-half_B)+ABS(($B33+$B$17:$B$22-half_B)))/2))))/2))/disp_B/disp_LL
A34: axle 3, right=B_ext | B34: =B_ext-half_B-$B$19 | C34: =SUMPRODUCT($E$17:$E$22*(((((($B34+$B$17:$B$22+half_B)+B_ext-ABS(($B34+$B$17:$B$22+half_B)-B_ext))/2)-((($B34+$B$17:$B$22-half_B)+ABS(($B34+$B$17:$B$22-half_B)))/2))+ABS((((($B34+$B$17:$B$22+half_B)+B_ext-ABS(($B34+$B$17:$B$22+half_B)-B_ext))/2)-((($B34+$B$17:$B$22-half_B)+ABS(($B34+$B$17:$B$22-half_B)))/2))))/2))/disp_B/disp_LL
A35: axle 3, left=0 | B35: =half_B-$B$19 | C35: =SUMPRODUCT($E$17:$E$22*(((((($B35+$B$17:$B$22+half_B)+B_ext-ABS(($B35+$B$17:$B$22+half_B)-B_ext))/2)-((($B35+$B$17:$B$22-half_B)+ABS(($B35+$B$17:$B$22-half_B)))/2))+ABS((((($B35+$B$17:$B$22+half_B)+B_ext-ABS(($B35+$B$17:$B$22+half_B)-B_ext))/2)-((($B35+$B$17:$B$22-half_B)+ABS(($B35+$B$17:$B$22-half_B)))/2))))/2))/disp_B/disp_LL
A36: axle 3, left=B_ext | B36: =B_ext+half_B-$B$19 | C36: =SUMPRODUCT($E$17:$E$22*(((((($B36+$B$17:$B$22+half_B)+B_ext-ABS(($B36+$B$17:$B$22+half_B)-B_ext))/2)-((($B36+$B$17:$B$22-half_B)+ABS(($B36+$B$17:$B$22-half_B)))/2))+ABS((((($B36+$B$17:$B$22+half_B)+B_ext-ABS(($B36+$B$17:$B$22+half_B)-B_ext))/2)-((($B36+$B$17:$B$22-half_B)+ABS(($B36+$B$17:$B$22-half_B)))/2))))/2))/disp_B/disp_LL
A37: axle 4, right=0 | B37: =-half_B-$B$20 | C37: =SUMPRODUCT($E$17:$E$22*(((((($B37+$B$17:$B$22+half_B)+B_ext-ABS(($B37+$B$17:$B$22+half_B)-B_ext))/2)-((($B37+$B$17:$B$22-half_B)+ABS(($B37+$B$17:$B$22-half_B)))/2))+ABS((((($B37+$B$17:$B$22+half_B)+B_ext-ABS(($B37+$B$17:$B$22+half_B)-B_ext))/2)-((($B37+$B$17:$B$22-half_B)+ABS(($B37+$B$17:$B$22-half_B)))/2))))/2))/disp_B/disp_LL
A38: axle 4, right=B_ext | B38: =B_ext-half_B-$B$20 | C38: =SUMPRODUCT($E$17:$E$22*(((((($B38+$B$17:$B$22+half_B)+B_ext-ABS(($B38+$B$17:$B$22+half_B)-B_ext))/2)-((($B38+$B$17:$B$22-half_B)+ABS(($B38+$B$17:$B$22-half_B)))/2))+ABS((((($B38+$B$17:$B$22+half_B)+B_ext-ABS(($B38+$B$17:$B$22+half_B)-B_ext))/2)-((($B38+$B$17:$B$22-half_B)+ABS(($B38+$B$17:$B$22-half_B)))/2))))/2))/disp_B/disp_LL
A39: axle 4, left=0 | B39: =half_B-$B$20 | C39: =SUMPRODUCT($E$17:$E$22*(((((($B39+$B$17:$B$22+half_B)+B_ext-ABS(($B39+$B$17:$B$22+half_B)-B_ext))/2)-((($B39+$B$17:$B$22-half_B)+ABS(($B39+$B$17:$B$22-half_B)))/2))+ABS((((($B39+$B$17:$B$22+half_B)+B_ext-ABS(($B39+$B$17:$B$22+half_B)-B_ext))/2)-((($B39+$B$17:$B$22-half_B)+ABS(($B39+$B$17:$B$22-half_B)))/2))))/2))/disp_B/disp_LL
A40: axle 4, left=B_ext | B40: =B_ext+half_B-$B$20 | C40: =SUMPRODUCT($E$17:$E$22*(((((($B40+$B$17:$B$22+half_B)+B_ext-ABS(($B40+$B$17:$B$22+half_B)-B_ext))/2)-((($B40+$B$17:$B$22-half_B)+ABS(($B40+$B$17:$B$22-half_B)))/2))+ABS((((($B40+$B$17:$B$22+half_B)+B_ext-ABS(($B40+$B$17:$B$22+half_B)-B_ext))/2)-((($B40+$B$17:$B$22-half_B)+ABS(($B40+$B$17:$B$22-half_B)))/2))))/2))/disp_B/disp_LL
A41: axle 5, right=0 | B41: =-half_B-$B$21 | C41: =SUMPRODUCT($E$17:$E$22*(((((($B41+$B$17:$B$22+half_B)+B_ext-ABS(($B41+$B$17:$B$22+half_B)-B_ext))/2)-((($B41+$B$17:$B$22-half_B)+ABS(($B41+$B$17:$B$22-half_B)))/2))+ABS((((($B41+$B$17:$B$22+half_B)+B_ext-ABS(($B41+$B$17:$B$22+half_B)-B_ext))/2)-((($B41+$B$17:$B$22-half_B)+ABS(($B41+$B$17:$B$22-half_B)))/2))))/2))/disp_B/disp_LL
A42: axle 5, right=B_ext | B42: =B_ext-half_B-$B$21 | C42: =SUMPRODUCT($E$17:$E$22*(((((($B42+$B$17:$B$22+half_B)+B_ext-ABS(($B42+$B$17:$B$22+half_B)-B_ext))/2)-((($B42+$B$17:$B$22-half_B)+ABS(($B42+$B$17:$B$22-half_B)))/2))+ABS((((($B42+$B$17:$B$22+half_B)+B_ext-ABS(($B42+$B$17:$B$22+half_B)-B_ext))/2)-((($B42+$B$17:$B$22-half_B)+ABS(($B42+$B$17:$B$22-half_B)))/2))))/2))/disp_B/disp_LL
A43: axle 5, left=0 | B43: =half_B-$B$21 | C43: =SUMPRODUCT($E$17:$E$22*(((((($B43+$B$17:$B$22+half_B)+B_ext-ABS(($B43+$B$17:$B$22+half_B)-B_ext))/2)-((($B43+$B$17:$B$22-half_B)+ABS(($B43+$B$17:$B$22-half_B)))/2))+ABS((((($B43+$B$17:$B$22+half_B)+B_ext-ABS(($B43+$B$17:$B$22+half_B)-B_ext))/2)-((($B43+$B$17:$B$22-half_B)+ABS(($B43+$B$17:$B$22-half_B)))/2))))/2))/disp_B/disp_LL
...

Sheet TableB4
A1: Table B.4 — Sliding & Overturning (Maximum Vertical)
A3: Sliding and overturning, LM1 and LM3, all four limit states — the smaller margin governs.
A5: Sliding & Overturning at SLS
A7: Common Terms — SLS (unfavourable/max)
A8: road_udl_char = UDL_1 (kN/m) | B8: =UDL_1
A9: fill_udl_char = UDL_total - UDL_1 (kN/m) | B9: =UDL_total-UDL_1
A10: surcharge_road = road_dev * road_udl_char (kN/m) | B10: =road_dev_unfav*B8
A11: active_surcharge = Ka_earth*gamma_super*(surcharge_road+fill_udl_char)*H_ext (kN) | B11: =Ka_earth_SLS*Superimposed_sup_SLS*(B10+B9)*H_ext
A12: passive_surcharge = Kmax*gamma_super*(surcharge_road+fill_udl_char)*H_ext (kN) | B12: =Kmax_SLS*Superimposed_sup_SLS*(B10+B9)*H_ext
A13: backfill_pressure = gamma_backfill * H_ext (kN/m2) | B13: =gamma_backfill*H_ext
A14: active_backfill = Ka_earth*gamma_self*backfill_pressure*H_ext/2 (kN) | B14: =Ka_earth_SLS*SelfWeight_sup_SLS*B13*H_ext/2
A15: passive_backfill = Kmax*gamma_self*backfill_pressure*H_ext/2 (kN) | B15: =Kmax_SLS*SelfWeight_sup_SLS*B13*H_ext/2
A16: total_passive = passive_surcharge + passive_backfill (kN) | B16: =B12+B15
A17: road_vertical = gamma_super * gamma_sd_ec * road_dev * road_udl_char * B_ext (kN) | B17: =Superimposed_sup_SLS*gamma_sd_ec*road_dev_unfav*B8*B_ext
A18: fill_vertical = gamma_super * gamma_sd_ec * fill_udl_char * B_ext (kN) | B18: =Superimposed_sup_SLS*gamma_sd_ec*B9*B_ext
A19: self_weight_vertical = gamma_self * W_box (kN) | B19: =SelfWeight_sup_SLS*W_box
A20: common_vertical = road_vertical + fill_vertical + self_weight_vertical (kN) | B20: =B17+B18+B19
A21: LM1 Scenario — SLS
A22: active_line_load = Ka_traffic*gamma_Q*F_hll_1m_coeff (kN) | B22: =Ka_traffic_SLS*RoadTraffic_sup_SLS*F_hll_1m_coeff
A23: active_udl = Ka_traffic*gamma_Q*20*H_ext (kN) | B23: =Ka_traffic_SLS*RoadTraffic_sup_SLS*20.0*H_ext
A24: braking_char (kN) | B24: =Q_lk/L_L
A25: braking = gamma_Q * braking_char (kN) | B25: =RoadTraffic_sup_SLS*B24
A26: total_active = active_surcharge+active_backfill+active_line_load+active_udl+braking (kN) | B26: =B11+B14+B22+B23+B25
A27: vertical_char (kN) | B27: =lane1_udl*B_ext+patch_load*disp_m*2
A28: vertical = gamma_Q * vertical_char (kN) | B28: =RoadTraffic_sup_SLS*B27
A29: V_d = common_vertical + vertical (kN) | B29: =B20+B28
A30: delta_d = ATAN(TAN(RADIANS(phi_founding))/gamma_M) (deg) | B30: =DEGREES(ATAN(TAN(RADIANS(phi_founding))/MaterialM_SLS))
A31: max_Rd = V_d * TAN(RADIANS(delta_d)) (kN) | B31: =B29*TAN(RADIANS(B30))
A32: friction_required = total_active - total_passive (kN) | B32: =B26-B16
A33: SLIDING margin = max_Rd - friction_required (kN) | B33: =B31-B32
A34: Sliding OK? (margin >= 0) | B34: =B33>=0
A35: UR_sliding = MAX(0,friction_required)/max_Rd (%) | B35: =MAX(0,B32)/B31*100
A36: M_active = act_surch*(H_ext/2)+act_bkfl*(H_ext/3)+line_load*H_ext+udl*(H_ext/2)+braking*H_ext (kNm) | B36: =B11*(H_ext/2)+B14*(H_ext/3)+B22*H_ext+B23*(H_ext/2)+B25*H_ext
A37: M_passive = pass_surch*(H_ext/2) + pass_bkfl*(H_ext/3) (kNm) | B37: =B12*(H_ext/2)+B15*(H_ext/3)
A38: M_driving = MAX(0, M_active - M_passive) (kNm) | B38: =MAX(0,B36-B37)
A39: M_stabilizing = V_d * B_ext/2 (kNm) | B39: =B29*B_ext/2
A40: OVERTURNING margin = M_stabilizing - M_driving (kNm) | B40: =B39-B38
A41: Overturning OK? (ot_margin >= 0) | B41: =B40>=0
A42: UR_overturning = MAX(0,M_driving)/M_stabilizing (%) | B42: =MAX(0,B38)/B39*100
A43: LM3 Scenario — SLS
...

Sheet TableB5
A1: Table B.5 — Sliding & Overturning (Minimum Vertical)
A3: Sliding and overturning, LM1 and LM3, all four limit states — the smaller margin governs.
A5: Sliding & Overturning at SLS
A7: Common Terms — SLS (favourable/min)
A8: road_udl_char = UDL_1 (kN/m) | B8: =UDL_1
A9: fill_udl_char = UDL_total - UDL_1 (kN/m) | B9: =UDL_total-UDL_1
A10: surcharge_road = road_dev * road_udl_char (kN/m) | B10: =road_dev_fav*B8
A11: active_surcharge = Ka_earth*gamma_super*(surcharge_road+fill_udl_char)*H_ext (kN) | B11: =Ka_earth_SLS*Superimposed_inf_SLS*(B10+B9)*H_ext
A12: passive_surcharge = Kmax*gamma_super*(surcharge_road+fill_udl_char)*H_ext (kN) | B12: =Kmax_SLS*Superimposed_inf_SLS*(B10+B9)*H_ext
A13: backfill_pressure = gamma_backfill * H_ext (kN/m2) | B13: =gamma_backfill*H_ext
A14: active_backfill = Ka_earth*gamma_self*backfill_pressure*H_ext/2 (kN) | B14: =Ka_earth_SLS*SelfWeight_inf_SLS*B13*H_ext/2
A15: passive_backfill = Kmax*gamma_self*backfill_pressure*H_ext/2 (kN) | B15: =Kmax_SLS*SelfWeight_inf_SLS*B13*H_ext/2
A16: total_passive = passive_surcharge + passive_backfill (kN) | B16: =B12+B15
A17: road_vertical = gamma_super * gamma_sd_ec * road_dev * road_udl_char * B_ext (kN) | B17: =Superimposed_inf_SLS*1*road_dev_fav*B8*B_ext
A18: fill_vertical = gamma_super * gamma_sd_ec * fill_udl_char * B_ext (kN) | B18: =Superimposed_inf_SLS*1*B9*B_ext
A19: self_weight_vertical = gamma_self * W_box (kN) | B19: =SelfWeight_inf_SLS*W_box
A20: common_vertical = road_vertical + fill_vertical + self_weight_vertical (kN) | B20: =B17+B18+B19
A21: LM1 Scenario — SLS
A22: active_line_load = Ka_traffic*gamma_Q*F_hll_1m_coeff (kN) | B22: =Ka_traffic_SLS*RoadTraffic_sup_SLS*F_hll_1m_coeff
A23: active_udl = Ka_traffic*gamma_Q*20*H_ext (kN) | B23: =Ka_traffic_SLS*RoadTraffic_sup_SLS*20.0*H_ext
A24: braking_char (kN) | B24: =Q_lk/L_L
A25: braking = gamma_Q * braking_char (kN) | B25: =RoadTraffic_sup_SLS*B24
A26: total_active = active_surcharge+active_backfill+active_line_load+active_udl+braking (kN) | B26: =B11+B14+B22+B23+B25
A27: vertical_char (kN) | B27: =lane1_udl*B_ext+patch_load*disp_m*2
A28: vertical = gamma_Q * vertical_char (kN) | B28: =RoadTraffic_sup_SLS*B27
A29: V_d = common_vertical + vertical (kN) | B29: =B20+B28
A30: delta_d = ATAN(TAN(RADIANS(phi_founding))/gamma_M) (deg) | B30: =DEGREES(ATAN(TAN(RADIANS(phi_founding))/MaterialM_SLS))
A31: max_Rd = V_d * TAN(RADIANS(delta_d)) (kN) | B31: =B29*TAN(RADIANS(B30))
A32: friction_required = total_active - total_passive (kN) | B32: =B26-B16
A33: SLIDING margin = max_Rd - friction_required (kN) | B33: =B31-B32
A34: Sliding OK? (margin >= 0) | B34: =B33>=0
A35: UR_sliding = MAX(0,friction_required)/max_Rd (%) | B35: =MAX(0,B32)/B31*100
A36: M_active = act_surch*(H_ext/2)+act_bkfl*(H_ext/3)+line_load*H_ext+udl*(H_ext/2)+braking*H_ext (kNm) | B36: =B11*(H_ext/2)+B14*(H_ext/3)+B22*H_ext+B23*(H_ext/2)+B25*H_ext
A37: M_passive = pass_surch*(H_ext/2) + pass_bkfl*(H_ext/3) (kNm) | B37: =B12*(H_ext/2)+B15*(H_ext/3)
A38: M_driving = MAX(0, M_active - M_passive) (kNm) | B38: =MAX(0,B36-B37)
A39: M_stabilizing = V_d * B_ext/2 (kNm) | B39: =B29*B_ext/2
A40: OVERTURNING margin = M_stabilizing - M_driving (kNm) | B40: =B39-B38
A41: Overturning OK? (ot_margin >= 0) | B41: =B40>=0
A42: UR_overturning = MAX(0,M_driving)/M_stabilizing (%) | B42: =MAX(0,B38)/B39*100
A43: LM3 Scenario — SLS
...

Sheet TableB6
A1: Table B.6 — Sliding & Overturning (Minimum Vertical + Water Table)
A3: Sliding and overturning, LM1 and LM3, all four limit states — the smaller margin governs.
A5: Buoyancy (Archimedes, submerged external cross-section)
A6: Submerged height = MIN(h_wt, H_ext) (m) | B6: =MIN(h_wt,H_ext)
A7: F_buoyancy_char = gamma_w * B_ext * submerged height (kN) | B7: =gamma_w*B_ext*B6
A9: Sliding & Overturning at SLS
A11: F_buoyancy = WaterPressure_sup_SLS * F_buoyancy_char (kN) | B11: =WaterPressure_sup_SLS*B7
A12: Common Terms — SLS (favourable/min)
A13: road_udl_char = UDL_1 (kN/m) | B13: =UDL_1
A14: fill_udl_char = UDL_total - UDL_1 (kN/m) | B14: =UDL_total-UDL_1
A15: surcharge_road = road_dev * road_udl_char (kN/m) | B15: =road_dev_fav*B13
A16: active_surcharge = Ka_earth*gamma_super*(surcharge_road+fill_udl_char)*H_ext (kN) | B16: =Ka_earth_SLS*Superimposed_inf_SLS*(B15+B14)*H_ext
A17: passive_surcharge = Kmax*gamma_super*(surcharge_road+fill_udl_char)*H_ext (kN) | B17: =Kmax_SLS*Superimposed_inf_SLS*(B15+B14)*H_ext
A18: backfill_pressure = gamma_backfill * H_ext (kN/m2) | B18: =gamma_backfill*H_ext
A19: active_backfill = Ka_earth*gamma_self*backfill_pressure*H_ext/2 (kN) | B19: =Ka_earth_SLS*SelfWeight_inf_SLS*B18*H_ext/2
A20: passive_backfill = Kmax*gamma_self*backfill_pressure*H_ext/2 (kN) | B20: =Kmax_SLS*SelfWeight_inf_SLS*B18*H_ext/2
A21: total_passive = passive_surcharge + passive_backfill (kN) | B21: =B17+B20
A22: road_vertical = gamma_super * gamma_sd_ec * road_dev * road_udl_char * B_ext (kN) | B22: =Superimposed_inf_SLS*1*road_dev_fav*B13*B_ext
A23: fill_vertical = gamma_super * gamma_sd_ec * fill_udl_char * B_ext (kN) | B23: =Superimposed_inf_SLS*1*B14*B_ext
A24: self_weight_vertical = gamma_self * W_box (kN) | B24: =SelfWeight_inf_SLS*W_box
A25: common_vertical = road_vertical + fill_vertical + self_weight_vertical (kN) | B25: =B22+B23+B24
A26: LM1 Scenario — SLS
A27: active_line_load = Ka_traffic*gamma_Q*F_hll_1m_coeff (kN) | B27: =Ka_traffic_SLS*RoadTraffic_sup_SLS*F_hll_1m_coeff
A28: active_udl = Ka_traffic*gamma_Q*20*H_ext (kN) | B28: =Ka_traffic_SLS*RoadTraffic_sup_SLS*20.0*H_ext
A29: braking_char (kN) | B29: =Q_lk/L_L
A30: braking = gamma_Q * braking_char (kN) | B30: =RoadTraffic_sup_SLS*B29
A31: total_active = active_surcharge+active_backfill+active_line_load+active_udl+braking (kN) | B31: =B16+B19+B27+B28+B30
A32: vertical_char (kN) | B32: =lane1_udl*B_ext+patch_load*disp_m*2
A33: vertical = gamma_Q * vertical_char (kN) | B33: =RoadTraffic_sup_SLS*B32
A34: V_d = common_vertical + vertical - buoyancy (kN) | B34: =B25+B33-B11
A35: delta_d = ATAN(TAN(RADIANS(phi_founding))/gamma_M) (deg) | B35: =DEGREES(ATAN(TAN(RADIANS(phi_founding))/MaterialM_SLS))
A36: max_Rd = V_d * TAN(RADIANS(delta_d)) (kN) | B36: =B34*TAN(RADIANS(B35))
A37: friction_required = total_active - total_passive (kN) | B37: =B31-B21
A38: SLIDING margin = max_Rd - friction_required (kN) | B38: =B36-B37
A39: Sliding OK? (margin >= 0) | B39: =B38>=0
A40: UR_sliding = MAX(0,friction_required)/max_Rd (%) | B40: =MAX(0,B37)/B36*100
A41: M_active = act_surch*(H_ext/2)+act_bkfl*(H_ext/3)+line_load*H_ext+udl*(H_ext/2)+braking*H_ext (kNm) | B41: =B16*(H_ext/2)+B19*(H_ext/3)+B27*H_ext+B28*(H_ext/2)+B30*H_ext
A42: M_passive = pass_surch*(H_ext/2) + pass_bkfl*(H_ext/3) (kNm) | B42: =B17*(H_ext/2)+B20*(H_ext/3)
A43: M_driving = MAX(0, M_active - M_passive) (kNm) | B43: =MAX(0,B41-B42)
A44: M_stabilizing = V_d * B_ext/2 (kNm) | B44: =B34*B_ext/2
...

Sheet Assumptions
A1: Assumptions
A3: - Design is carried out on a 1.0 m strip basis.
A4: - The structure has no longitudinal joints, so full load dispersal through the fill can be considered (PD6694-1 Cl. 10.2.7) — dispersal is not curtailed by a segment joint.
A5: - The Transverse Dispersal formula assumes the dispersed wheel width is at least the 1.0 m design strip width. This requires H_c >= 0.52 m — not checked in this workbook.
A6: - Per PD6694-1 Cl. 10.2.1, dispersal through fill is only valid for H_c >= 0.6 m; below that the structure should be treated as a normal bridge deck with undispersed traffic loading — not enforced or flagged here.
A7: - The Transverse Dispersal formula assumes only two adjacent wheels' dispersion zones overlap in the critical 1 m strip (lanes 1 & 2 only) — not extended to 3+ overlapping wheels.
A8: - Road construction (cover Layer 1) is treated separately from fill (remaining layers) for the +55%/-40% construction-thickness deviation — an assumption carried over from the source Streamlit app, not explicitly stated in PD6694-1.
A9: - LM3's worst vehicle position is found by evaluating the exact breakpoints of the (piecewise-linear) landed-load-vs-offset function, rather than a fine numerical scan — mathematically equivalent to (and more precise than) the Streamlit app's 0.01 m grid search; cross-checked against it for SV196 (163.8 kN/m, matching to 3 s.f.).
A10: - LM3 braking force = delta x (sum of characteristic axle loads), delta = 0.50/0.40/0.25 for SV80/SV100/SV196 (NA.2.18.1) — algebraically identical to summing per-axle-group braking forces, since delta is constant per vehicle.
A11: - Table B.6 buoyancy = gamma_w x B_ext x MIN(h_wt, H_ext) (Archimedes, submerged external cross-section) — a discrete uplift force, not a change to backfill unit weight or earth pressure coefficients below the water table.
A12: - Bearing pressure (PD6694-1 Cl. 10.3.2) is not covered by this workbook — sliding and overturning only.
A13: - This workbook is a direct transcription of the culvert-stability Streamlit app's calculation logic into live Excel formulas — see that app's own Assumptions tab for further detail on individual modelling choices.
